Workbook

Sheet resumen
B9: REPORTE DE INSUMOS CRITICOS
B18: INVENTARIO DE QUIMICOS | J18: INVENTARIO DE GASES
B20: QUIMICOS | C20: Inventario Inicial | D20: CONSUMO DIARIO (3 LOTES) | E20: Consumo (23/06/26) | F20: Cantidades Minimas | G20: Existencia | H20: DÍAS DE PRODUCCIÓN CON LA EXISTENCIA ACTUAL | J20: GASES | K20: LLENAS | L20: EN USO | M20: Vacias
B21: Acido Clorhidrico (Lts) | C21: 6235 | D21: 216 | E21: 216 | F21: 860 | G21: =+quimicos!AG7 -> 902 | H21: =+G21/D21 -> 4.1759259 | J21: Propano | K21: 1 | L21: 5 | M21: 0
B22: Acido Nitrico (Lts) | C22: 3510 | D22: 120 | E22: 72 | F22: 500 | G22: =+quimicos!AG8 -> 1018 | H22: =+G22/D22 -> 8.4833333 | J22: Oxigeno | K22: 2 | L22: 1 | M22: 4
B23: Metalbisulfito (kg) | C23: 1625 | D23: 75 | E23: 72 | F23: 300 | G23: =+quimicos!AG9 -> 2553 | H23: =+G23/D23 -> 34.04 | J23: Argon | K23: 4 | L23: 1 | M23: 0
B24: Urea (kg) | C24: 5900 | D24: 72 | E24: 72 | F24: 600 | G24: =+quimicos!AG10 -> 4028 | H24: =+G24/D24 -> 55.944444
B25: Soda Caustica (Lts) | C25: 350 | D25: Por ahora sin uso | E25: 0 | F25: 120 | G25: =+quimicos!AG11 -> 350 | H25: N/A
B26: Soda Caustica (Kg) | C26: 1800 | D26: 24 Kg/mes | E26: 0 | F26: 250 | G26: =+quimicos!AG12 -> 1804 | H26: MAYOR A 1 AÑO
B27: Amoniaco (Lts) | C27: 1880 | D27: 60 | E27: 60 | F27: 500 | G27: =+quimicos!AG13 -> 340 | H27: =+G27/D27 -> 5.6666667
B28: Alcohol Etilico (Lts) | C28: 190 | D28: 4 | E28: 0 | F28: 40 | G28: =+quimicos!AG14 -> 80 | H28: =+G28/D28 -> 20
J33: GASOIL
J34: DISPONIBLE (LTS) | K34: =+combustible!D9 -> 5067

Sheet quimicos
B4: INVENTARIO DE QUIMICOS
B6: QUIMICOS | C6: Inventario Inicial | D6: Consumo (28/05/26) | E6: Consumo (29/05/26) | F6: Consumo (30/05/26) | G6: Consumo (31/05/26) | H6: Consumo (01/06/26) | I6: Consumo (02/06/26) | J6: Consumo (03/06/26) | K6: Consumo (04/06/26) | L6: Consumo (05/06/26) | M6: Consumo (06/06/26) | N6: Consumo (07/06/26) | O6: Consumo (08/06/26) | P6: Consumo (09/06/26) | Q6: Consumo (10/06/26) | R6: Consumo (11/06/26) | S6: Consumo (12/06/26) | T6: Consumo (13/06/26) | U6: Consumo (14/06/26) | V6: Consumo (15/06/26) | W6: Consumo (16/06/26) | X6: Consumo (16/06/26) | Y6: Consumo (17/06/26) | Z6: Consumo (18/06/26) | AA6: Consumo (19/06/26) | AB6: Consumo (20/06/26) | AC6: Ajustes por consumos (21/06/26) | AD6: Consumo (21/06/26) | AE6: Ajuste | AF6: Consumo (23/06/26) | AG6: Existencia
B7: Acido Clorhidrico (Lts) | C7: =5655+294 -> 5949 | D7: 216 | E7: 216 | F7: 216 | G7: 216 | H7: 216 | I7: 216 | J7: 216 | K7: 216 | L7: 216 | M7: 216 | N7: 216 | O7: 216 | P7: 216 | Q7: 216 | R7: 216 | S7: 216 | T7: 216 | U7: 216 | V7: 216 | W7: 0 | X7: 216 | Y7: 216 | Z7: 216 | AA7: 216 | AB7: 216 | AC7: 231 | AD7: 216 | AE7: 338 | AF7: 216 | AG7: =+C7-D7-E7-F7-G7-H7-I7-J7-K7-L7-M7-N7-O7-P7-Q7-R7-S7-T7-U7-V7-X7-Y7-Z7+W7-AA7-AB7-AD7+AC7+AE7-AF7 -> 902 | AH7: =+AC7+AG7 -> 1133
B8: Acido Nitrico (Lts) | C8: =3732-21 -> 3711 | D8: 120 | E8: 102 | F8: 102 | G8: 102 | H8: 102 | I8: 72 | J8: 72 | K8: 72 | L8: 72 | M8: 72 | N8: 72 | O8: 72 | P8: 72 | Q8: 72 | R8: 72 | S8: 72 | T8: 72 | U8: 72 | V8: 72 | W8: 0 | X8: 72 | Y8: 72 | Z8: 72 | AA8: 72 | AB8: 72 | AC8: -378 | AD8: 72 | AE8: -275 | AF8: 72 | AG8: =+C8-D8-E8-F8-G8-H8-I8-J8-K8-L8-M8-N8-O8-P8-Q8-R8-S8-T8-U8-V8-X8-Y8-Z8+W8-AA8-AB8-AD8+AC8+AE8-AF8 -> 1018 | AH8: =+AC8+AG8 -> 640 | AK8: ,
B9: Metalbisulfito (kg) | C9: =1625-6 -> 1619 | D9: 75 | E9: 75 | F9: 74 | G9: 75 | H9: 72 | I9: 72 | J9: 72 | K9: 72 | L9: 72 | M9: 72 | N9: 72 | O9: 72 | P9: 72 | Q9: 72 | R9: 72 | S9: 72 | T9: 72 | U9: 72 | V9: 72 | W9: 1000 | X9: 72 | Y9: 72 | Z9: 72 | AA9: 72 | AB9: 72 | AC9: 1967 | AD9: 72 | AE9: -150 | AF9: 72 | AG9: =+C9-D9-E9-F9-G9-H9-I9-J9-K9-L9-M9-N9-O9-P9-Q9-R9-S9-T9-U9-V9-X9-Y9-Z9+W9-AA9-AB9-AD9+AC9+AE9-AF9 -> 2553 | AH9: =+AC9+AG9 -> 4520
B10: Urea (kg) | C10: =5900-24 -> 5876 | D10: 70 | E10: 72 | F10: 72 | G10: 72 | H10: 72 | I10: 72 | J10: 72 | K10: 72 | L10: 72 | M10: 72 | N10: 42 | O10: 72 | P10: 72 | Q10: 72 | R10: 72 | S10: 72 | T10: 72 | U10: 72 | V10: 72 | W10: 0 | X10: 72 | Y10: 72 | Z10: 72 | AA10: 72 | AB10: 72 | AC10: 0 | AD10: 72 | AE10: -8 | AF10: 72 | AG10: =+C10-D10-E10-F10-G10-H10-I10-J10-K10-L10-M10-N10-O10-P10-Q10-R10-S10-T10-U10-V10-X10-Y10-Z10+W10-AA10-AB10-AD10+AC10+AE10-AF10 -> 4028 | AH10: =+AC10+AG10 -> 4028
B11: Soda Caustica (Lts) | C11: 350 | D11: 0 | E11: 0 | F11: 0 | G11: 0 | H11: 0 | I11: 0 | J11: 0 | K11: 0 | L11: 0 | M11: 0 | N11: 0 | O11: 0 | P11: 0 | Q11: 0 | R11: 0 | S11: 0 | T11: 0 | U11: 0 | V11: 0 | W11: 0 | X11: 0 | Y11: 0 | Z11: 0 | AA11: 0 | AB11: 0 | AC11: 0 | AD11: 0 | AE11: 0 | AF11: 0 | AG11: =+C11-D11-E11-F11-G11-H11-I11-J11-K11-L11-M11-N11-O11-P11-Q11-R11-S11-T11-U11-V11-X11-Y11-Z11+W11-AA11-AB11-AD11+AC11+AE11-AF11 -> 350 | AH11: =+AC11+AG11 -> 350
B12: Soda Caustica (Kg) | C12: 1800 | D12: 0 | E12: 0 | F12: 0 | G12: 0 | H12: 0 | I12: 0 | J12: 0 | K12: 0 | L12: 0 | M12: 0 | N12: 0 | O12: 0 | P12: 0 | Q12: 0 | R12: 0 | S12: 0 | T12: 0 | U12: 0 | V12: 0 | W12: 0 | X12: 0 | Y12: 0 | Z12: 0 | AA12: 0 | AB12: 0 | AC12: 0 | AD12: 0 | AE12: 4 | AF12: 0 | AG12: =+C12-D12-E12-F12-G12-H12-I12-J12-K12-L12-M12-N12-O12-P12-Q12-R12-S12-T12-U12-V12-X12-Y12-Z12+W12-AA12-AB12-AD12+AC12+AE12-AF12 -> 1804 | AH12: =+AC12+AG12 -> 1804
B13: Amoniaco (Lts) | C13: =1880-46 -> 1834 | D13: 60 | E13: 60 | F13: 54 | G13: 60 | H13: 60 | I13: 60 | J13: 60 | K13: 60 | L13: 60 | M13: 60 | N13: 60 | O13: 60 | P13: 60 | Q13: 60 | R13: 60 | S13: 60 | T13: 60 | U13: 60 | V13: 60 | W13: 0 | X13: 60 | Y13: 60 | Z13: 60 | AA13: 60 | AB13: 60 | AC13: 180 | AD13: 60 | AE13: -120 | AF13: 60 | AG13: =+C13-D13-E13-F13-G13-H13-I13-J13-K13-L13-M13-N13-O13-P13-Q13-R13-S13-T13-U13-V13-X13-Y13-Z13+W13-AA13-AB13-AD13+AC13+AE13-AF13 -> 340 | AH13: =+AC13+AG13 -> 520
B14: Alcohol Etilico (Lts) | C14: 190 | D14: 4 | E14: 0 | F14: 4 | G14: 0 | H14: 4 | I14: 0 | J14: 0 | K14: 20 | L14: 0 | M14: 0 | N14: 0 | O14: 0 | P14: 0 | Q14: 8 | R14: 0 | S14: 0 | T14: 0 | U14: 0 | V14: 0 | W14: 0 | X14: 0 | Y14: 0 | Z14: 0 | AA14: 0 | AB14: 0 | AC14: 0 | AD14: 0 | AE14: -70 | AF14: 0 | AG14: =+C14-D14-E14-F14-G14-H14-I14-J14-K14-L14-M14-N14-O14-P14-Q14-R14-S14-T14-U14-V14-X14-Y14-Z14+W14-AA14-AB14-AD14+AC14+AE14-AF14 -> 80 | AH14: =+AC14+AG14 -> 80

Sheet gases
B4: INVENTARIO DE GASES
B6: GASES | C6: LLENAS | D6: EN USO | E6: DISPONIBLES
B7: Propano | C7: 1 | D7: 2 | E7: 1
B8: Oxigeno | C8: 0 | D8: 1 | E8: 7
B9: Argon | C9: 0 | D9: 1 | E9: 4

Sheet combustible
C4: CONTROL DIARO DE COMBUSTIBLE
C6: CANTIDAD INICIAL: | D6: 21449
C9: DISPONIBLE (LTS) | D9: =+D70 -> 5067
C12: FECHA | D12: CONSUMO (LTS) | E12: DISPONIBLE (LTS)
C13: 46174 | D13: 3000 | E13: =D6-D13 -> 18449 | H13: =+D9-8067 -> -3000
C14: 46175 | D14: 413 | E14: =+E13-D14 -> 18036
C15: 46175 | D15: 60 | E15: =+E14-D15 -> 17976
C16: 46178 | D16: 2050 | E16: =+E15-D16 -> 15926
C17: 46181 | D17: 2046 | E17: =+E16-D17 -> 13880
C18: 46186 | D18: 1000 | E18: =+E17-D18 -> 12880
C19: 46188 | D19: 1000 | E19: =+E18-D19 -> 11880
C20: 46192 | D20: 3813 | E20: =+E19-D20 -> 8067
C21: 46194 | D21: 1000 | E21: =+E20-D21 -> 7067
C22: 46196 | D22: 2000 | E22: =+E21-D22 -> 5067
E23: =+E22-D23 -> 5067
E24: =+E23-D24 -> 5067
E25: =+E24-D25 -> 5067
E26: =+E25-D26 -> 5067
E27: =+E26-D27 -> 5067
E28: =+E27-D28 -> 5067
E29: =+E28-D29 -> 5067
E30: =+E29-D30 -> 5067
E31: =+E30-D31 -> 5067
E32: =+E31-D32 -> 5067
E33: =+E32-D33 -> 5067
E34: =+E33-D34 -> 5067
... E55: =+E54-D55 -> 5067
E56: =+E55+D56 -> 5067
E57: =+E56-D57 -> 5067
E58: =+E57-D58 -> 5067
E59: =+E58-D59 -> 5067
E60: =+E59-D60 -> 5067
E61: =+E60-D61 -> 5067
E62: =+E61-D62 -> 5067
E63: =+E62-D63 -> 5067
E64: =+E63-D64 -> 5067
E65: =+E64-D65 -> 5067
E66: =+E65-D66 -> 5067
E67: =+E66-D67 -> 5067
E68: =+E67-D68 -> 5067
...

Sheet NOVEDADES
B7: NOVEDADES
B9: EQUIPO | C9: DIAGNOSTICO | D9: ACCION
B10: Generador del campamento | C10: No encendia, se reemplazo el modulo eim, queda corregida la falla ▪️ El radiador esta totalmente tapado con peluza, (se debe lavar externamente ▪️ La velocidad del motor no es estable, la bomba de inyeccion requiere servicio. ▪️Ruido irregular en el motor (sera necesario desmontar la camara para evaluar) | D10: Ya esta en manos de nelson desde el sabado 20/06/2026
B11: Extractor | C11: Persiste las rupturas de correas por falla en diseno de poleas | D11: en espera de que baje equipo de contreras para corregir falla
B12: Horno azul grande | C12: presenta falla en el bobina | D12: Hoy me terminaron de entregar la otra bobina. Lo que estamos viendo es que al parecer no es 100% cobre. Que esas tuberías qué están vendiendo tienen aleación y eso afecta la inducción.
B13: Casting bar | C13: Esta presentado goteo interno (sudorazion en las paredes) | D13: No se pudo hacer prueba por falla en el generador grande por el sensor de presion de aceite y que estaban en uso los hornos por fundicion
